Workbook

Sheet School Contacts
A1: School District | B1: School Name | C1: School Type (Middle/High/Combined) | D1: Contact Full Name | E1: Job Title | F1: Relevant Department or Club | G1: Professional Email Address | H1: Email Verification Status | I1: Email Source URL | J1: School Website | K1: Priority (High/Medium/Low) | L1: Notes
A2: Clayton County Public Schools | B2: Adamson Middle School | C2: Middle | D2: Segeeta Allen-Bland | E2: Teacher-Computer Tech Mid Sch | F2: Computer Technology (Connections) | G2: segeeta.allenbland@clayton.k12.ga.us | H2: Verified - official school staff directory (profile) | I2: https://019.clayton.k12.ga.us/staff/directory | J2: https://019.clayton.k12.ga.us | K2: High
A3: Clayton County Public Schools | B3: Adamson Middle School | C3: Middle | D3: Adrian Courtland | E3: Principal-Middle School | F3: Administration | G3: adrian.courtland@clayton.k12.ga.us | H3: Verified - official school staff directory (profile) | I3: https://019.clayton.k12.ga.us/staff/directory | J3: https://019.clayton.k12.ga.us | K3: High
A4: Clayton County Public Schools | B4: Adamson Middle School | C4: Middle | D4: Lakesha Roberts | E4: Ast Principal-Middle School | F4: Administration | G4: lakesha.roberts@clayton.k12.ga.us | H4: Verified - official school staff directory (profile) | I4: https://019.clayton.k12.ga.us/staff/directory | J4: https://019.clayton.k12.ga.us | K4: Medium
A5: Clayton County Public Schools | B5: Adamson Middle School | C5: Middle | D5: Melody Powell | E5: Ast Principal-Middle School | F5: Administration | G5: melody.powell@clayton.k12.ga.us | H5: Verified - official school staff directory (profile) | I5: https://019.clayton.k12.ga.us/staff/directory | J5: https://019.clayton.k12.ga.us | K5: Medium
A6: Clayton County Public Schools | B6: Adamson Middle School | C6: Middle | D6: Aaleyah Kelso | E6: Teacher-Science Middle School | F6: Science | G6: aaleyah.kelso@clayton.k12.ga.us | H6: Verified - official school staff directory (profile) | I6: https://019.clayton.k12.ga.us/staff/directory | J6: https://019.clayton.k12.ga.us | K6: Low
A7: Clayton County Public Schools | B7: Carrie D. Kendrick Middle School | C7: Middle | D7: Monique Lewis | E7: Teacher-Computer Tech Mid Sch | F7: Computer Technology (Connections) | G7: monique.lewis@clayton.k12.ga.us | H7: Verified - official school staff directory (profile) | I7: https://028.clayton.k12.ga.us/staff | J7: https://024.clayton.k12.ga.us | K7: High | L7: Directory profile lists multiple locations: Kendrick Ms, Sequoyah Ms.
A8: Clayton County Public Schools | B8: Carrie D. Kendrick Middle School | C8: Middle | D8: Letitia Lewis | E8: Principal-Middle School | F8: Administration | G8: letitia.lewis@clayton.k12.ga.us | H8: Verified - official school staff directory (profile) | I8: https://024.clayton.k12.ga.us/staff/directory | J8: https://024.clayton.k12.ga.us | K8: High
A9: Clayton County Public Schools | B9: Carrie D. Kendrick Middle School | C9: Middle | D9: Charles Gilchrist | E9: Ast Principal-Middle School | F9: Administration | G9: charles.gilchrist@clayton.k12.ga.us | H9: Verified - official school staff directory (profile) | I9: https://024.clayton.k12.ga.us/staff/directory | J9: https://024.clayton.k12.ga.us | K9: Medium
A10: Clayton County Public Schools | B10: Carrie D. Kendrick Middle School | C10: Middle | D10: Kantrell Gibson-Brown | E10: Ast Principal-Middle School | F10: Administration | G10: kantrell.gibson-brown@clayton.k12.ga.us | H10: Verified - official school staff directory (profile) | I10: https://024.clayton.k12.ga.us/staff/directory | J10: https://024.clayton.k12.ga.us | K10: Medium
A11: Clayton County Public Schools | B11: Carrie D. Kendrick Middle School | C11: Middle | D11: Cadine Ferguson | E11: Intalage Teachers-Science | F11: Science | G11: cadine.ferguson@clayton.k12.ga.us | H11: Verified - official school staff directory (profile) | I11: https://024.clayton.k12.ga.us/staff/directory | J11: https://024.clayton.k12.ga.us | K11: Low
A12: Clayton County Public Schools | B12: Eddie White Middle Academy | C12: Middle | D12: Lynna Springs | E12: Teacher-Computer Tech Mid Sch | F12: Computer Technology (Connections) | G12: lynna.springs@clayton.k12.ga.us | H12: Verified - official school staff directory (profile) | I12: https://031.clayton.k12.ga.us/staff | J12: https://031.clayton.k12.ga.us | K12: High
A13: Clayton County Public Schools | B13: Eddie White Middle Academy | C13: Middle | D13: Shannon Hoskins-Praylow | E13: Teacher-Computer Tech Mid Sch | F13: Computer Technology (Connections) | G13: shannon.hoskinsprayl@clayton.k12.ga.us | H13: Verified - official school staff directory (profile) | I13: https://031.clayton.k12.ga.us/staff | J13: https://031.clayton.k12.ga.us | K13: High
A14: Clayton County Public Schools | B14: Eddie White Middle Academy | C14: Middle | D14: Micki Harris | E14: Principal-Middle School | F14: Administration | G14: micki.harris@clayton.k12.ga.us | H14: Verified - official school staff directory (profile) | I14: https://031.clayton.k12.ga.us/staff | J14: https://031.clayton.k12.ga.us | K14: High
A15: Clayton County Public Schools | B15: Eddie White Middle Academy | C15: Middle | D15: Sharlissa Pollard | E15: Teacher-Technology Middle Sch | F15: Technology (Connections) | G15: sharlissa.pollard@clayton.k12.ga.us | H15: Verified - official school staff directory (profile) | I15: https://031.clayton.k12.ga.us/staff | J15: https://031.clayton.k12.ga.us | K15: High | L15: Directory profile lists multiple locations: Marshall Es, White Academy Ms.
A16: Clayton County Public Schools | B16: Eddie White Middle Academy | C16: Middle | D16: Adriel Thomas | E16: Teacher-Science Middle School | F16: Science | G16: adriel.thomas@clayton.k12.ga.us | H16: Verified - official school staff directory (profile) | I16: https://031.clayton.k12.ga.us/staff | J16: https://031.clayton.k12.ga.us | K16: Low
A17: Clayton County Public Schools | B17: Forest Park Middle School | C17: Middle | D17: Thomas Stinson | E17: Engineering/Technology Teacher | F17: Engineering & Technology (Connections) | G17: thomas.stinson@clayton.k12.ga.us | H17: Verified - official school staff directory (profile) | I17: https://012.clayton.k12.ga.us/staff/directory | J17: https://012.clayton.k12.ga.us | K17: High | L17: Directory title Teacher-Engineering/Technology MS (profile assigned to Forest Park MS). A Mr. Stinson is also named as Technology & Robotics Club contact on Adamson MS's club page, which appears out of date.
A18: Clayton County Public Schools | B18: Forest Park Middle School | C18: Middle | D18: Ramona Potts | E18: Teacher-Computer Tech Mid Sch | F18: Computer Technology (Connections) | G18: ramona.potts@clayton.k12.ga.us | H18: Verified - official school staff directory (profile) | I18: https://012.clayton.k12.ga.us/staff/directory | J18: https://012.clayton.k12.ga.us | K18: High
A19: Clayton County Public Schools | B19: Forest Park Middle School | C19: Middle | D19: Harold Dobbins | E19: Principal-Middle School | F19: Administration | G19: harold.dobbins@clayton.k12.ga.us | H19: Verified - official school staff directory (profile) | I19: https://012.clayton.k12.ga.us/staff/directory | J19: https://012.clayton.k12.ga.us | K19: High | L19: Directory profile lists multiple locations: East Clayton Es, Forest Park Ms.
A20: Clayton County Public Schools | B20: Forest Park Middle School | C20: Middle | D20: Sara Vasquez | E20: Ast Principal-Middle School | F20: Administration | G20: sara.vasquez@clayton.k12.ga.us | H20: Verified - official school staff directory (profile) | I20: https://012.clayton.k12.ga.us/staff/directory | J20: https://012.clayton.k12.ga.us | K20: Medium
A21: Clayton County Public Schools | B21: Forest Park Middle School | C21: Middle | D21: Chasity Jackson | E21: Teacher-Science Middle School | F21: Science | G21: chasity.jackson@clayton.k12.ga.us | H21: Verified - official school staff directory (profile) | I21: https://012.clayton.k12.ga.us/staff/directory | J21: https://012.clayton.k12.ga.us | K21: Low
A22: Clayton County Public Schools | B22: G.P. Babb Middle School | C22: Middle | D22: Nakia Cole | E22: Science Teacher; Drone & Robotics Team co-lead | F22: Drone & Robotics Team / Science | G22: nakia.cole@clayton.k12.ga.us | H22: Verified - published on official school webpage | I22: https://011.clayton.k12.ga.us/about/points-of-pride | J22: https://011.clayton.k12.ga.us | K22: High | L22: Points of Pride (3/7/2026) credits Ms. Cole with the Drone & Robotics team.
A23: Clayton County Public Schools | B23: G.P. Babb Middle School | C23: Middle | D23: Taylor Milam | E23: Teacher-Ib/Magnet/stem-Secondary | F23: Magnet/STEM Program | G23: taylor.milam@clayton.k12.ga.us | H23: Verified - official school staff directory (profile) | I23: https://011.clayton.k12.ga.us/staff | J23: https://011.clayton.k12.ga.us | K23: High
A24: Clayton County Public Schools | B24: G.P. Babb Middle School | C24: Middle | D24: Ashley Young | E24: Teacher-Computer Science | F24: Computer Science (CTAE) | G24: ashley.young@clayton.k12.ga.us | H24: Verified - official school staff directory (profile) | I24: https://011.clayton.k12.ga.us/staff | J24: https://011.clayton.k12.ga.us | K24: High
A25: Clayton County Public Schools | B25: G.P. Babb Middle School | C25: Middle | D25: Deborah Green | E25: Principal-Middle School | F25: Administration | G25: deborah.green@clayton.k12.ga.us | H25: Verified - official school staff directory (profile) | I25: https://011.clayton.k12.ga.us/staff | J25: https://011.clayton.k12.ga.us | K25: High
A26: Clayton County Public Schools | B26: G.P. Babb Middle School | C26: Middle | D26: Adeline Bazard | E26: Teacher-Science Middle School | F26: Science | G26: adeline.bazard@clayton.k12.ga.us | H26: Verified - official school staff directory (profile) | I26: https://011.clayton.k12.ga.us/staff | J26: https://011.clayton.k12.ga.us | K26: Low
A27: Clayton County Public Schools | B27: Jonesboro Middle School | C27: Middle | D27: Kim Nguyen | E27: Teacher-Technology Middle Sch | F27: Technology (Connections) | G27: kim.nguyen@clayton.k12.ga.us | H27: Verified - official school staff directory (profile) | I27: https://014.clayton.k12.ga.us/staff/directory | J27: https://014.clayton.k12.ga.us | K27: High
A28: Clayton County Public Schools | B28: Jonesboro Middle School | C28: Middle | D28: Onequa Hampshire | E28: Teacher-Computer Tech Mid Sch | F28: Computer Technology (Connections) | G28: onequa.hampshire@clayton.k12.ga.us | H28: Verified - official school staff directory (profile) | I28: https://014.clayton.k12.ga.us/staff/directory | J28: https://014.clayton.k12.ga.us | K28: High
A29: Clayton County Public Schools | B29: Jonesboro Middle School | C29: Middle | D29: Kimberlee Barnett | E29: Principal-Middle School | F29: Administration | G29: kimberlee.barnett@clayton.k12.ga.us | H29: Verified - official school staff directory (profile) | I29: https://014.clayton.k12.ga.us/staff/directory | J29: https://014.clayton.k12.ga.us | K29: High
A30: Clayton County Public Schools | B30: Jonesboro Middle School | C30: Middle | D30: Wendy Thompson | E30: Teacher-Gifted Science | F30: Science | G30: wendy.thompson@clayton.k12.ga.us | H30: Verified - official school staff directory (profile) | I30: https://014.clayton.k12.ga.us/staff/directory | J30: https://014.clayton.k12.ga.us | K30: Medium
A31: Clayton County Public Schools | B31: Jonesboro Middle School | C31: Middle | D31: Michael Walraven | E31: Ast Principal-Middle School | F31: Administration | G31: michael.walraven@clayton.k12.ga.us | H31: Verified - official school staff directory (profile) | I31: https://014.clayton.k12.ga.us/staff/directory | J31: https://014.clayton.k12.ga.us | K31: Medium
A32: Clayton County Public Schools | B32: M.D. Roberts School of the Arts | C32: Middle | D32: Jessie Henry | E32: Computer Science Teacher | F32: Computer Science (Connections) | G32: jessie.henry@clayton.k12.ga.us | H32: Verified - published on official school webpage | I32: https://025.clayton.k12.ga.us/staff/directory | J32: https://025.clayton.k12.ga.us | K32: High
A33: Clayton County Public Schools | B33: M.D. Roberts School of the Arts | C33: Middle | D33: Dr. Caryn Turner | E33: Principal | F33: Administration | G33: caryn.turner@clayton.k12.ga.us | H33: Verified - published on official school webpage | I33: https://025.clayton.k12.ga.us/about/administration | J33: https://025.clayton.k12.ga.us | K33: High | L33: mailto link on Administration page (capitalized as Caryn.turner@).
A34: Clayton County Public Schools | B34: M.D. Roberts School of the Arts | C34: Middle | D34: Dr. Stacy Black | E34: Assistant Principal | F34: Administration | G34: stacy.black@clayton.k12.ga.us | H34: Verified - published on official school webpage | I34: https://025.clayton.k12.ga.us/about/administration | J34: https://025.clayton.k12.ga.us | K34: Medium | L34: Email rendered by the page's Finalsite email script. Grade-level assignment differs between page sections (7th grade listed).
A35: Clayton County Public Schools | B35: M.D. Roberts School of the Arts | C35: Middle | D35: Torressa Smith | E35: Physical Science Teacher (8th grade) | F35: Science | G35: torressa.smith@clayton.k12.ga.us | H35: Verified - published on official school webpage | I35: https://025.clayton.k12.ga.us/staff/directory | J35: https://025.clayton.k12.ga.us | K35: Low
A36: Clayton County Public Schools | B36: M.D. Roberts School of the Arts | C36: Middle | D36: Gary Lomba | E36: Assistant Principal (Fine Arts) | F36: Administration | G36: gary.lomba@clayton.k12.ga.us | H36: Verified - published on official school webpage | I36: https://025.clayton.k12.ga.us/about/administration | J36: https://025.clayton.k12.ga.us | K36: Low | L36: Email rendered by the page's Finalsite email script.
A37: Clayton County Public Schools | B37: Morrow Middle School | C37: Middle | D37: Valencia Smith | E37: Teacher-Computer Tech Mid Sch | F37: Computer Technology (Connections) | G37: valencia.smith@clayton.k12.ga.us | H37: Verified - official school staff directory (profile) | I37: https://015.clayton.k12.ga.us/staff | J37: https://015.clayton.k12.ga.us | K37: High
A38: Clayton County Public Schools | B38: Morrow Middle School | C38: Middle | D38: Christopher Robinson | E38: Principal-Middle School | F38: Administration | G38: christopher.robinson@clayton.k12.ga.us | H38: Verified - official school staff directory (profile) | I38: https://015.clayton.k12.ga.us/staff | J38: https://015.clayton.k12.ga.us | K38: High
A39: Clayton County Public Schools | B39: Morrow Middle School | C39: Middle | D39: Deon Pennyman | E39: Teacher-Gifted Science | F39: Science | G39: deon.pennyman@clayton.k12.ga.us | H39: Verified - official school staff directory (profile) | I39: https://015.clayton.k12.ga.us/staff | J39: https://015.clayton.k12.ga.us | K39: Medium
A40: Clayton County Public Schools | B40: Morrow Middle School | C40: Middle | D40: David Johnson | E40: Ast Principal-Middle School | F40: Administration | G40: david.johnson@clayton.k12.ga.us | H40: Verified - official school staff directory (profile) | I40: https://015.clayton.k12.ga.us/staff | J40: https://015.clayton.k12.ga.us | K40: Medium
...

Sheet Complete School List
A1: School District | B1: School Name | C1: School Type | D1: Grades Served | E1: Official School Website | F1: Official Directory Source | G1: Number of Verified Contacts Found | H1: Research Status | I1: Notes
A2: Clayton County Public Schools | B2: Adamson Middle School | C2: Middle | D2: 6-8 | E2: https://019.clayton.k12.ga.us | F2: https://www.clayton.k12.ga.us/about/district-schools | G2: =COUNTIFS('School Contacts'!$B$2:$B$304,B2,'School Contacts'!$H$2:$H$304,"Verified*") -> 5 | H2: =IF(G2>=3,"Complete - 3+ verified contacts",IF(G2>0,"Partial - limited public contact info","No verified contacts found")) -> Complete - 3+ verified contacts | I2: Technology & Robotics Club page names "Mr. Stinson", who is now assigned to Forest Park MS per directory profile; no current Adamson robotics sponsor identified.
A3: Clayton County Public Schools | B3: Carrie D. Kendrick Middle School | C3: Middle | D3: 6-8 | E3: https://024.clayton.k12.ga.us | F3: https://www.clayton.k12.ga.us/about/district-schools | G3: =COUNTIFS('School Contacts'!$B$2:$B$304,B3,'School Contacts'!$H$2:$H$304,"Verified*") -> 5 | H3: =IF(G3>=3,"Complete - 3+ verified contacts",IF(G3>0,"Partial - limited public contact info","No verified contacts found")) -> Complete - 3+ verified contacts | I3: About page mis-links some staff emails (e.g., principal link points to another person); directory profile addresses used instead.
A4: Clayton County Public Schools | B4: Eddie White Middle Academy | C4: Middle | D4: 6-8 | E4: https://031.clayton.k12.ga.us | F4: https://www.clayton.k12.ga.us/about/district-schools | G4: =COUNTIFS('School Contacts'!$B$2:$B$304,B4,'School Contacts'!$H$2:$H$304,"Verified*") -> 5 | H4: =IF(G4>=3,"Complete - 3+ verified contacts",IF(G4>0,"Partial - limited public contact info","No verified contacts found")) -> Complete - 3+ verified contacts
A5: Clayton County Public Schools | B5: Forest Park Middle School | C5: Middle | D5: 6-8 | E5: https://012.clayton.k12.ga.us | F5: https://www.clayton.k12.ga.us/about/district-schools | G5: =COUNTIFS('School Contacts'!$B$2:$B$304,B5,'School Contacts'!$H$2:$H$304,"Verified*") -> 5 | H5: =IF(G5>=3,"Complete - 3+ verified contacts",IF(G5>0,"Partial - limited public contact info","No verified contacts found")) -> Complete - 3+ verified contacts
A6: Clayton County Public Schools | B6: G.P. Babb Middle School | C6: Middle | D6: 6-8 | E6: https://011.clayton.k12.ga.us | F6: https://www.clayton.k12.ga.us/about/district-schools | G6: =COUNTIFS('School Contacts'!$B$2:$B$304,B6,'School Contacts'!$H$2:$H$304,"Verified*") -> 5 | H6: =IF(G6>=3,"Complete - 3+ verified contacts",IF(G6>0,"Partial - limited public contact info","No verified contacts found")) -> Complete - 3+ verified contacts | I6: Drone & Robotics team (Points of Pride 3/2026).
A7: Clayton County Public Schools | B7: Jonesboro Middle School | C7: Middle | D7: 6-8 | E7: https://014.clayton.k12.ga.us | F7: https://www.clayton.k12.ga.us/about/district-schools | G7: =COUNTIFS('School Contacts'!$B$2:$B$304,B7,'School Contacts'!$H$2:$H$304,"Verified*") -> 5 | H7: =IF(G7>=3,"Complete - 3+ verified contacts",IF(G7>0,"Partial - limited public contact info","No verified contacts found")) -> Complete - 3+ verified contacts
A8: Clayton County Public Schools | B8: M.D. Roberts School of the Arts | C8: Middle | D8: 6-8 | E8: https://025.clayton.k12.ga.us | F8: https://www.clayton.k12.ga.us/about/district-schools | G8: =COUNTIFS('School Contacts'!$B$2:$B$304,B8,'School Contacts'!$H$2:$H$304,"Verified*") -> 5 | H8: =IF(G8>=3,"Complete - 3+ verified contacts",IF(G8>0,"Partial - limited public contact info","No verified contacts found")) -> Complete - 3+ verified contacts | I8: Fine arts magnet. Staff directory is a plain table (no titles beyond subject).
A9: Clayton County Public Schools | B9: Morrow Middle School | C9: Middle | D9: 6-8 | E9: https://015.clayton.k12.ga.us | F9: https://www.clayton.k12.ga.us/about/district-schools | G9: =COUNTIFS('School Contacts'!$B$2:$B$304,B9,'School Contacts'!$H$2:$H$304,"Verified*") -> 5 | H9: =IF(G9>=3,"Complete - 3+ verified contacts",IF(G9>0,"Partial - limited public contact info","No verified contacts found")) -> Complete - 3+ verified contacts
A10: Clayton County Public Schools | B10: Mundy's Mill Middle School | C10: Middle | D10: 6-8 | E10: https://016.clayton.k12.ga.us | F10: https://www.clayton.k12.ga.us/about/district-schools | G10: =COUNTIFS('School Contacts'!$B$2:$B$304,B10,'School Contacts'!$H$2:$H$304,"Verified*") -> 5 | H10: =IF(G10>=3,"Complete - 3+ verified contacts",IF(G10>0,"Partial - limited public contact info","No verified contacts found")) -> Complete - 3+ verified contacts | I10: S.T.E.A.M. school with a designated STEM Lead.
A11: Clayton County Public Schools | B11: North Clayton Middle School | C11: Middle | D11: 6-8 | E11: https://017.clayton.k12.ga.us | F11: https://www.clayton.k12.ga.us/about/district-schools | G11: =COUNTIFS('School Contacts'!$B$2:$B$304,B11,'School Contacts'!$H$2:$H$304,"Verified*") -> 5 | H11: =IF(G11>=3,"Complete - 3+ verified contacts",IF(G11>0,"Partial - limited public contact info","No verified contacts found")) -> Complete - 3+ verified contacts | I11: Magnet program (grant-funded Magnet Specialist).
A12: Clayton County Public Schools | B12: Pointe South Middle School | C12: Middle | D12: 6-8 | E12: https://020.clayton.k12.ga.us | F12: https://www.clayton.k12.ga.us/about/district-schools | G12: =COUNTIFS('School Contacts'!$B$2:$B$304,B12,'School Contacts'!$H$2:$H$304,"Verified*") -> 5 | H12: =IF(G12>=3,"Complete - 3+ verified contacts",IF(G12>0,"Partial - limited public contact info","No verified contacts found")) -> Complete - 3+ verified contacts
A13: Clayton County Public Schools | B13: Rex Mill Middle School | C13: Middle | D13: 6-8 | E13: https://029.clayton.k12.ga.us | F13: https://www.clayton.k12.ga.us/about/district-schools | G13: =COUNTIFS('School Contacts'!$B$2:$B$304,B13,'School Contacts'!$H$2:$H$304,"Verified*") -> 5 | H13: =IF(G13>=3,"Complete - 3+ verified contacts",IF(G13>0,"Partial - limited public contact info","No verified contacts found")) -> Complete - 3+ verified contacts | I13: STEM magnet middle school.
A14: Clayton County Public Schools | B14: Riverdale Middle School | C14: Middle | D14: 6-8 | E14: https://018.clayton.k12.ga.us | F14: https://www.clayton.k12.ga.us/about/district-schools | G14: =COUNTIFS('School Contacts'!$B$2:$B$304,B14,'School Contacts'!$H$2:$H$304,"Verified*") -> 5 | H14: =IF(G14>=3,"Complete - 3+ verified contacts",IF(G14>0,"Partial - limited public contact info","No verified contacts found")) -> Complete - 3+ verified contacts
A15: Clayton County Public Schools | B15: Sequoyah Middle School | C15: Middle | D15: 6-8 | E15: https://028.clayton.k12.ga.us | F15: https://www.clayton.k12.ga.us/about/district-schools | G15: =COUNTIFS('School Contacts'!$B$2:$B$304,B15,'School Contacts'!$H$2:$H$304,"Verified*") -> 5 | H15: =IF(G15>=3,"Complete - 3+ verified contacts",IF(G15>0,"Partial - limited public contact info","No verified contacts found")) -> Complete - 3+ verified contacts
A16: Clayton County Public Schools | B16: Utopian Academy for the Arts Middle School | C16: Middle | D16: 6-8 | E16: https://utopianacademyforthearts.com/middleschoolhome/ | F16: https://www.clayton.k12.ga.us/departments/charter-school-petition-guidelines/ccps-charter-schools ; GOSA Enrollment by Grade 2024-25: https://download.gosa.ga.gov/2025/Enrollment_by_Grade_2024-25_2026-02-19_00_31_56.csv | G16: =COUNTIFS('School Contacts'!$B$2:$B$304,B16,'School Contacts'!$H$2:$H$304,"Verified*") -> 5 | H16: =IF(G16>=3,"Complete - 3+ verified contacts",IF(G16>0,"Partial - limited public contact info","No verified contacts found")) -> Complete - 3+ verified contacts | I16: Charter school (Clayton campus) listed on CCPS charter page; reported under Clayton County in GOSA data.
A17: Clayton County Public Schools | B17: Charles R. Drew High School | C17: High | D17: 9-12 | E17: https://315.clayton.k12.ga.us | F17: https://www.clayton.k12.ga.us/about/district-schools | G17: =COUNTIFS('School Contacts'!$B$2:$B$304,B17,'School Contacts'!$H$2:$H$304,"Verified*") -> 5 | H17: =IF(G17>=3,"Complete - 3+ verified contacts",IF(G17>0,"Partial - limited public contact info","No verified contacts found")) -> Complete - 3+ verified contacts
A18: Clayton County Public Schools | B18: Forest Park High School | C18: High | D18: 9-12 | E18: https://001.clayton.k12.ga.us | F18: https://www.clayton.k12.ga.us/about/district-schools | G18: =COUNTIFS('School Contacts'!$B$2:$B$304,B18,'School Contacts'!$H$2:$H$304,"Verified*") -> 5 | H18: =IF(G18>=3,"Complete - 3+ verified contacts",IF(G18>0,"Partial - limited public contact info","No verified contacts found")) -> Complete - 3+ verified contacts | I18: Has Robotics Club and TSA chapter.
A19: Clayton County Public Schools | B19: Jonesboro High School | C19: High | D19: 9-12 | E19: https://002.clayton.k12.ga.us | F19: https://www.clayton.k12.ga.us/about/district-schools | G19: =COUNTIFS('School Contacts'!$B$2:$B$304,B19,'School Contacts'!$H$2:$H$304,"Verified*") -> 5 | H19: =IF(G19>=3,"Complete - 3+ verified contacts",IF(G19>0,"Partial - limited public contact info","No verified contacts found")) -> Complete - 3+ verified contacts | I19: Department pages conflict on Andrew Cox role/email (see contact note).
A20: Clayton County Public Schools | B20: Lovejoy High School | C20: High | D20: 9-12 | E20: https://006.clayton.k12.ga.us | F20: https://www.clayton.k12.ga.us/about/district-schools | G20: =COUNTIFS('School Contacts'!$B$2:$B$304,B20,'School Contacts'!$H$2:$H$304,"Verified*") -> 5 | H20: =IF(G20>=3,"Complete - 3+ verified contacts",IF(G20>0,"Partial - limited public contact info","No verified contacts found")) -> Complete - 3+ verified contacts | I20: No engineering, computer science or robotics staff identifiable in directory titles or pages; CTI teacher used.
A21: Clayton County Public Schools | B21: Martha Ellen Stilwell School of the Arts | C21: High | D21: 9-12 | E21: https://316.clayton.k12.ga.us | F21: https://www.clayton.k12.ga.us/about/district-schools | G21: =COUNTIFS('School Contacts'!$B$2:$B$304,B21,'School Contacts'!$H$2:$H$304,"Verified*") -> 5 | H21: =IF(G21>=3,"Complete - 3+ verified contacts",IF(G21>0,"Partial - limited public contact info","No verified contacts found")) -> Complete - 3+ verified contacts | I21: Performing arts high school (GOSA: grades 9-12). No STEM/CTAE-titled staff in directory.
A22: Clayton County Public Schools | B22: Morrow High School | C22: High | D22: 9-12 | E22: https://003.clayton.k12.ga.us | F22: https://www.clayton.k12.ga.us/about/district-schools | G22: =COUNTIFS('School Contacts'!$B$2:$B$304,B22,'School Contacts'!$H$2:$H$304,"Verified*") -> 5 | H22: =IF(G22>=3,"Complete - 3+ verified contacts",IF(G22>0,"Partial - limited public contact info","No verified contacts found")) -> Complete - 3+ verified contacts
A23: Clayton County Public Schools | B23: Mount Zion High School | C23: High | D23: 9-12 | E23: https://007.clayton.k12.ga.us | F23: https://www.clayton.k12.ga.us/about/district-schools | G23: =COUNTIFS('School Contacts'!$B$2:$B$304,B23,'School Contacts'!$H$2:$H$304,"Verified*") -> 5 | H23: =IF(G23>=3,"Complete - 3+ verified contacts",IF(G23>0,"Partial - limited public contact info","No verified contacts found")) -> Complete - 3+ verified contacts
A24: Clayton County Public Schools | B24: Mundy's Mill High School | C24: High | D24: 9-12 | E24: https://311.clayton.k12.ga.us | F24: https://www.clayton.k12.ga.us/about/district-schools | G24: =COUNTIFS('School Contacts'!$B$2:$B$304,B24,'School Contacts'!$H$2:$H$304,"Verified*") -> 5 | H24: =IF(G24>=3,"Complete - 3+ verified contacts",IF(G24>0,"Partial - limited public contact info","No verified contacts found")) -> Complete - 3+ verified contacts | I24: STEM Program page exists but names no staff; no engineering/CS-titled staff in directory.
A25: Clayton County Public Schools | B25: North Clayton High School | C25: High | D25: 9-12 | E25: https://004.clayton.k12.ga.us | F25: https://www.clayton.k12.ga.us/about/district-schools | G25: =COUNTIFS('School Contacts'!$B$2:$B$304,B25,'School Contacts'!$H$2:$H$304,"Verified*") -> 5 | H25: =IF(G25>=3,"Complete - 3+ verified contacts",IF(G25>0,"Partial - limited public contact info","No verified contacts found")) -> Complete - 3+ verified contacts | I25: CTAE page names Gwendolyn Jones as CTAE Department Chair, but no email or directory entry found for her.
A26: Clayton County Public Schools | B26: Riverdale High School | C26: High | D26: 9-12 | E26: https://005.clayton.k12.ga.us | F26: https://www.clayton.k12.ga.us/about/district-schools | G26: =COUNTIFS('School Contacts'!$B$2:$B$304,B26,'School Contacts'!$H$2:$H$304,"Verified*") -> 5 | H26: =IF(G26>=3,"Complete - 3+ verified contacts",IF(G26>0,"Partial - limited public contact info","No verified contacts found")) -> Complete - 3+ verified contacts
A27: Clayton County Public Schools | B27: Perry Career Academy | C27: High | D27: 9-12 | E27: https://312.clayton.k12.ga.us | F27: https://www.clayton.k12.ga.us/about/district-schools ; GOSA Enrollment by Grade 2024-25: https://download.gosa.ga.gov/2025/Enrollment_by_Grade_2024-25_2026-02-19_00_31_56.csv | G27: =COUNTIFS('School Contacts'!$B$2:$B$304,B27,'School Contacts'!$H$2:$H$304,"Verified*") -> 5 | H27: =IF(G27>=3,"Complete - 3+ verified contacts",IF(G27>0,"Partial - limited public contact info","No verified contacts found")) -> Complete - 3+ verified contacts | I27: Alternative/career high school (Eula Wilburn Ponds Perry Center for Learning).
A28: Clayton County Public Schools | B28: Utopian Academy for the Arts High School | C28: High | D28: 9-12 | E28: https://utopianacademyforthearts.com/uafahighschool/ | F28: https://www.clayton.k12.ga.us/departments/charter-school-petition-guidelines/ccps-charter-schools ; https://scsc.georgia.gov/document/document/2025-2026-master-charter-school-list/download | G28: =COUNTIFS('School Contacts'!$B$2:$B$304,B28,'School Contacts'!$H$2:$H$304,"Verified*") -> 5 | H28: =IF(G28>=3,"Complete - 3+ verified contacts",IF(G28>0,"Partial - limited public contact info","No verified contacts found")) -> Complete - 3+ verified contacts | I28: Clayton-authorized charter. Principal email not published.
A29: Clayton County Public Schools | B29: Elite Scholars Academy | C29: Combined | D29: 6-12 | E29: https://099.clayton.k12.ga.us | F29: https://www.clayton.k12.ga.us/about/district-schools ; GOSA Enrollment by Grade 2024-25: https://download.gosa.ga.gov/2025/Enrollment_by_Grade_2024-25_2026-02-19_00_31_56.csv | G29: =COUNTIFS('School Contacts'!$B$2:$B$304,B29,'School Contacts'!$H$2:$H$304,"Verified*") -> 5 | H29: =IF(G29>=3,"Complete - 3+ verified contacts",IF(G29>0,"Partial - limited public contact info","No verified contacts found")) -> Complete - 3+ verified contacts
A30: Clayton County Public Schools | B30: Tapestry Public Charter School (Clayton campus) | C30: Combined | D30: 6-12 (state 2025-26 list shows 6-10 for opening year) | E30: https://tapestrycharter.org/clayton/ | F30: https://www.clayton.k12.ga.us/departments/charter-school-petition-guidelines/ccps-charter-schools ; https://scsc.georgia.gov/document/document/2025-2026-master-charter-school-list/download | G30: =COUNTIFS('School Contacts'!$B$2:$B$304,B30,'School Contacts'!$H$2:$H$304,"Verified*") -> 1 | H30: =IF(G30>=3,"Complete - 3+ verified contacts",IF(G30>0,"Partial - limited public contact info","No verified contacts found")) -> Partial - limited public contact info | I30: New Clayton-authorized charter opened Fall 2026 (not yet in GOSA data). Faculty directory publishes names only, no emails.
A31: Clayton County Public Schools | B31: Alternative Virtual Academy | C31: Combined | D31: Middle & high (alternative/virtual program) | E31: https://6008.clayton.k12.ga.us | F31: https://www.clayton.k12.ga.us/about/district-schools | G31: =COUNTIFS('School Contacts'!$B$2:$B$304,B31,'School Contacts'!$H$2:$H$304,"Verified*") -> 0 | H31: =IF(G31>=3,"Complete - 3+ verified contacts",IF(G31>0,"Partial - limited public contact info","No verified contacts found")) -> No verified contacts found | I31: Program listed by district; not reported as a separate school by GOSA. Site publishes only counselor/generic emails and no named leadership.
A32: Clayton County Public Schools | B32: Ash Street Center (South Metro GNETS) | C32: Combined | D32: Multi-grade (GNETS therapeutic program) | E32: https://009.clayton.k12.ga.us | F32: https://www.clayton.k12.ga.us/about/district-schools | G32: =COUNTIFS('School Contacts'!$B$2:$B$304,B32,'School Contacts'!$H$2:$H$304,"Verified*") -> 1 | H32: =IF(G32>=3,"Complete - 3+ verified contacts",IF(G32>0,"Partial - limited public contact info","No verified contacts found")) -> Partial - limited public contact info | I32: Georgia Network for Educational & Therapeutic Support program for students with IEPs; not a standard school. Low fit; director only.
A33: Cherokee County School District | B33: Creekland Middle School | C33: Middle | D33: 6-8 | E33: https://cms.cherokeek12.net | F33: https://www.cherokeek12.net/schools ; GOSA Enrollment by Grade 2024-25: https://download.gosa.ga.gov/2025/Enrollment_by_Grade_2024-25_2026-02-19_00_31_56.csv | G33: =COUNTIFS('School Contacts'!$B$2:$B$304,B33,'School Contacts'!$H$2:$H$304,"Verified*") -> 5 | H33: =IF(G33>=3,"Complete - 3+ verified contacts",IF(G33>0,"Partial - limited public contact info","No verified contacts found")) -> Complete - 3+ verified contacts
A34: Cherokee County School District | B34: Dean Rusk Middle School | C34: Middle | D34: 6-8 | E34: https://drms.cherokeek12.net | F34: https://www.cherokeek12.net/schools ; GOSA Enrollment by Grade 2024-25: https://download.gosa.ga.gov/2025/Enrollment_by_Grade_2024-25_2026-02-19_00_31_56.csv | G34: =COUNTIFS('School Contacts'!$B$2:$B$304,B34,'School Contacts'!$H$2:$H$304,"Verified*") -> 5 | H34: =IF(G34>=3,"Complete - 3+ verified contacts",IF(G34>0,"Partial - limited public contact info","No verified contacts found")) -> Complete - 3+ verified contacts
A35: Cherokee County School District | B35: E.T. Booth Middle School | C35: Middle | D35: 6-8 | E35: https://etbms.cherokeek12.net | F35: https://www.cherokeek12.net/schools ; GOSA Enrollment by Grade 2024-25: https://download.gosa.ga.gov/2025/Enrollment_by_Grade_2024-25_2026-02-19_00_31_56.csv | G35: =COUNTIFS('School Contacts'!$B$2:$B$304,B35,'School Contacts'!$H$2:$H$304,"Verified*") -> 4 | H35: =IF(G35>=3,"Complete - 3+ verified contacts",IF(G35>0,"Partial - limited public contact info","No verified contacts found")) -> Complete - 3+ verified contacts | I35: Faculty/Staff page renders empty (checked with a headless browser); only the administration team could be verified.
A36: Cherokee County School District | B36: Freedom Middle School | C36: Middle | D36: 6-8 | E36: https://fms.cherokeek12.net | F36: https://www.cherokeek12.net/schools ; GOSA Enrollment by Grade 2024-25: https://download.gosa.ga.gov/2025/Enrollment_by_Grade_2024-25_2026-02-19_00_31_56.csv | G36: =COUNTIFS('School Contacts'!$B$2:$B$304,B36,'School Contacts'!$H$2:$H$304,"Verified*") -> 5 | H36: =IF(G36>=3,"Complete - 3+ verified contacts",IF(G36>0,"Partial - limited public contact info","No verified contacts found")) -> Complete - 3+ verified contacts | I36: Has a Robotics Connections teacher.
A37: Cherokee County School District | B37: Mill Creek Middle School | C37: Middle | D37: 6-8 | E37: https://mcms.cherokeek12.net | F37: https://www.cherokeek12.net/schools ; GOSA Enrollment by Grade 2024-25: https://download.gosa.ga.gov/2025/Enrollment_by_Grade_2024-25_2026-02-19_00_31_56.csv | G37: =COUNTIFS('School Contacts'!$B$2:$B$304,B37,'School Contacts'!$H$2:$H$304,"Verified*") -> 5 | H37: =IF(G37>=3,"Complete - 3+ verified contacts",IF(G37>0,"Partial - limited public contact info","No verified contacts found")) -> Complete - 3+ verified contacts | I37: School Council page still lists a former principal.
A38: Cherokee County School District | B38: Teasley Middle School | C38: Middle | D38: 6-8 | E38: https://tms.cherokeek12.net | F38: https://www.cherokeek12.net/schools ; GOSA Enrollment by Grade 2024-25: https://download.gosa.ga.gov/2025/Enrollment_by_Grade_2024-25_2026-02-19_00_31_56.csv | G38: =COUNTIFS('School Contacts'!$B$2:$B$304,B38,'School Contacts'!$H$2:$H$304,"Verified*") -> 4 | H38: =IF(G38>=3,"Complete - 3+ verified contacts",IF(G38>0,"Partial - limited public contact info","No verified contacts found")) -> Complete - 3+ verified contacts | I38: Faculty directory labels elective teachers only as "Connections", so STEM/CS teachers could not be identified. ("TSA" here = Teacher Support Administrator.)
A39: Cherokee County School District | B39: Woodstock Middle School | C39: Middle | D39: 6-8 | E39: https://wms.cherokeek12.net | F39: https://www.cherokeek12.net/schools ; GOSA Enrollment by Grade 2024-25: https://download.gosa.ga.gov/2025/Enrollment_by_Grade_2024-25_2026-02-19_00_31_56.csv | G39: =COUNTIFS('School Contacts'!$B$2:$B$304,B39,'School Contacts'!$H$2:$H$304,"Verified*") -> 5 | H39: =IF(G39>=3,"Complete - 3+ verified contacts",IF(G39>0,"Partial - limited public contact info","No verified contacts found")) -> Complete - 3+ verified contacts
A40: Cherokee County School District | B40: Cherokee High School | C40: High | D40: 9-12 | E40: https://chs.cherokeek12.net | F40: https://www.cherokeek12.net/schools ; GOSA Enrollment by Grade 2024-25: https://download.gosa.ga.gov/2025/Enrollment_by_Grade_2024-25_2026-02-19_00_31_56.csv | G40: =COUNTIFS('School Contacts'!$B$2:$B$304,B40,'School Contacts'!$H$2:$H$304,"Verified*") -> 4 | H40: =IF(G40>=3,"Complete - 3+ verified contacts",IF(G40>0,"Partial - limited public contact info","No verified contacts found")) -> Complete - 3+ verified contacts | I40: No faculty email directory published; principal and assistant principals (by department oversight) only. AP CS teacher named without email.
...

Sheet Research Summary
A1: SwayForm Fall 2027 Outreach - Research Summary (Clayton, Cherokee, Forsyth)
A2: Research conducted October 30, 2026. Counts below are live formulas over the other two sheets.
A4: Metric | B4: Clayton County Public Schools | C4: Cherokee County School District | D4: Forsyth County Schools | E4: Total
A5: Middle schools identified | B5: =COUNTIFS('Complete School List'!$A$2:$A$67,"Clayton County Public Schools",'Complete School List'!$C$2:$C$67,"Middle") -> 15 | C5: =COUNTIFS('Complete School List'!$A$2:$A$67,"Cherokee County School District",'Complete School List'!$C$2:$C$67,"Middle") -> 7 | D5: =COUNTIFS('Complete School List'!$A$2:$A$67,"Forsyth County Schools",'Complete School List'!$C$2:$C$67,"Middle") -> 11 | E5: =SUM(B5:D5) -> 33
A6: High schools identified | B6: =COUNTIFS('Complete School List'!$A$2:$A$67,"Clayton County Public Schools",'Complete School List'!$C$2:$C$67,"High") -> 12 | C6: =COUNTIFS('Complete School List'!$A$2:$A$67,"Cherokee County School District",'Complete School List'!$C$2:$C$67,"High") -> 7 | D6: =COUNTIFS('Complete School List'!$A$2:$A$67,"Forsyth County Schools",'Complete School List'!$C$2:$C$67,"High") -> 8 | E6: =SUM(B6:D6) -> 27
A7: Combined-grade schools / programs identified | B7: =COUNTIFS('Complete School List'!$A$2:$A$67,"Clayton County Public Schools",'Complete School List'!$C$2:$C$67,"Combined") -> 4 | C7: =COUNTIFS('Complete School List'!$A$2:$A$67,"Cherokee County School District",'Complete School List'!$C$2:$C$67,"Combined") -> 1 | D7: =COUNTIFS('Complete School List'!$A$2:$A$67,"Forsyth County Schools",'Complete School List'!$C$2:$C$67,"Combined") -> 1 | E7: =SUM(B7:D7) -> 6
A8: Total unique schools researched | B8: =COUNTIFS('Complete School List'!$A$2:$A$67,"Clayton County Public Schools") -> 31 | C8: =COUNTIFS('Complete School List'!$A$2:$A$67,"Cherokee County School District") -> 15 | D8: =COUNTIFS('Complete School List'!$A$2:$A$67,"Forsyth County Schools") -> 20 | E8: =SUM(B8:D8) -> 66
A9: Total verified contacts (rows) | B9: =COUNTIFS('School Contacts'!$A$2:$A$304,"Clayton County Public Schools",'School Contacts'!$H$2:$H$304,"Verified*") -> 142 | C9: =COUNTIFS('School Contacts'!$A$2:$A$304,"Cherokee County School District",'School Contacts'!$H$2:$H$304,"Verified*") -> 66 | D9: =COUNTIFS('School Contacts'!$A$2:$A$304,"Forsyth County Schools",'School Contacts'!$H$2:$H$304,"Verified*") -> 92 | E9: =SUM(B9:D9) -> 300
A10: Contacts listed without a published email (not usable) | B10: =COUNTIFS('School Contacts'!$A$2:$A$304,"Clayton County Public Schools",'School Contacts'!$H$2:$H$304,"Not publicly available*") -> 2 | C10: =COUNTIFS('School Contacts'!$A$2:$A$304,"Cherokee County School District",'School Contacts'!$H$2:$H$304,"Not publicly available*") -> 1 | D10: =COUNTIFS('School Contacts'!$A$2:$A$304,"Forsyth County Schools",'School Contacts'!$H$2:$H$304,"Not publicly available*") -> 0 | E10: =SUM(B10:D10) -> 3
A11: High-priority verified contacts | B11: =COUNTIFS('School Contacts'!$A$2:$A$304,"Clayton County Public Schools",'School Contacts'!$H$2:$H$304,"Verified*",'School Contacts'!$K$2:$K$304,"High") -> 79 | C11: =COUNTIFS('School Contacts'!$A$2:$A$304,"Cherokee County School District",'School Contacts'!$H$2:$H$304,"Verified*",'School Contacts'!$K$2:$K$304,"High") -> 39 | D11: =COUNTIFS('School Contacts'!$A$2:$A$304,"Forsyth County Schools",'School Contacts'!$H$2:$H$304,"Verified*",'School Contacts'!$K$2:$K$304,"High") -> 59 | E11: =SUM(B11:D11) -> 177
A12: Schools with 3-5 verified contacts | B12: =COUNTIFS('Complete School List'!$A$2:$A$67,"Clayton County Public Schools",'Complete School List'!$G$2:$G$67,">=3") -> 28 | C12: =COUNTIFS('Complete School List'!$A$2:$A$67,"Cherokee County School District",'Complete School List'!$G$2:$G$67,">=3") -> 13 | D12: =COUNTIFS('Complete School List'!$A$2:$A$67,"Forsyth County Schools",'Complete School List'!$G$2:$G$67,">=3") -> 20 | E12: =SUM(B12:D12) -> 61
A13: Schools with 1-2 verified contacts (insufficient) | B13: =COUNTIFS('Complete School List'!$A$2:$A$67,"Clayton County Public Schools",'Complete School List'!$G$2:$G$67,">=1",'Complete School List'!$G$2:$G$67,"<=2") -> 2 | C13: =COUNTIFS('Complete School List'!$A$2:$A$67,"Cherokee County School District",'Complete School List'!$G$2:$G$67,">=1",'Complete School List'!$G$2:$G$67,"<=2") -> 2 | D13: =COUNTIFS('Complete School List'!$A$2:$A$67,"Forsyth County Schools",'Complete School List'!$G$2:$G$67,">=1",'Complete School List'!$G$2:$G$67,"<=2") -> 0 | E13: =SUM(B13:D13) -> 4
A14: Schools with 0 verified contacts | B14: =COUNTIFS('Complete School List'!$A$2:$A$67,"Clayton County Public Schools",'Complete School List'!$G$2:$G$67,0) -> 1 | C14: =COUNTIFS('Complete School List'!$A$2:$A$67,"Cherokee County School District",'Complete School List'!$G$2:$G$67,0) -> 0 | D14: =COUNTIFS('Complete School List'!$A$2:$A$67,"Forsyth County Schools",'Complete School List'!$G$2:$G$67,0) -> 0 | E14: =SUM(B14:D14) -> 1
A15: Unique people with verified emails (a few staff serve 2 schools) | E15: 293 | F15: Computed in Python from distinct addresses on School Contacts sheet.
A17: Schools with insufficient or limited publicly available contact information
A18: (See "Number of Verified Contacts Found" on the Complete School List for exact counts.)
A19: - Tapestry Public Charter School (Clayton campus) (Clayton): New Clayton-authorized charter opened Fall 2026 (not yet in GOSA data). Faculty directory publishes names only, no emails.
A20: - Alternative Virtual Academy (Clayton): Program listed by district; not reported as a separate school by GOSA. Site publishes only counselor/generic emails and no named leadership.
A21: - Ash Street Center (South Metro GNETS) (Clayton): Georgia Network for Educational & Therapeutic Support program for students with IEPs; not a standard school. Low fit; director only.
A22: - E.T. Booth Middle School (Cherokee): Faculty/Staff page renders empty (checked with a headless browser); only the administration team could be verified.
A23: - Teasley Middle School (Cherokee): Faculty directory labels elective teachers only as "Connections", so STEM/CS teachers could not be identified. ("TSA" here = Teacher Support Administrator.)
A24: - Cherokee High School (Cherokee): No faculty email directory published; principal and assistant principals (by department oversight) only. AP CS teacher named without email.
A25: - i-Grad Virtual Academy (Cherokee): Part of Active Academies; shares administration with ACE Academy.
A26: - ACE Academy (Cherokee): Alternative program within Active Academies (not reported separately by GOSA); shares administration with i-Grad.
A27: - Hendricks Middle School (Forsyth): Computer Science page does not name its teacher.
A29: Methodology
... A56: - All counts in this summary are formulas and update automatically if rows are added or removed.
